Workbook
Name _Ref225575190: 'Inventory Table'!$K$112
Name _Toc1473195: 'Inventory Table'!$K$100
Name Bar_Gal: [4]Corrections!$K$2
Name Bar_Gal: [4]Corrections!$K$2
Name BBtuToBtu: Factors!$J$49
Name BBtuToBtu: Factors!$J$49
Name BBtuToBtu: Factors!$J$49
Name BBtuToBtu: Factors!$J$49
Name BBtuToTBtu: [4]Consumption!$K$2
Name BBtuToTBtu: [4]Consumption!$K$2
Name CO2toC: Factors!$J$45
Name CO2toC: Factors!$J$45
Name CO2toC: Factors!$J$45
Name CO2toC: Factors!$J$45
Name CtoCO2: Factors!$J$44
Name CtoCO2: Factors!$J$44
Name CtoCO2: Factors!$J$44
Name CtoCO2: Factors!$J$44
Name CtoCO2: Factors!$J$44
Name CtoCO2: Factors!$J$44
Name CtoCO2: Factors!$J$44
Name CtoCO2: Factors!$J$44
Name CtoCO2: Factors!$J$44
Name CtoCO2: Factors!$J$44
Name CtoCO2: Factors!$J$44
Name CtoCO2: Factors!$J$44
Name CtoCO2: Factors!$J$44
Name CtoCO2: Factors!$J$44
Name CtoCO2: Factors!$J$44
Name CtoCO2: Factors!$J$44
Name CtoCO2: Factors!$J$44
Name CtoCO2: Factors!$J$44
Name CtoCO2: Factors!$J$44
Name CtoCO2: Factors!$J$44
Name CtoCO2: Factors!$J$44
Name CtoCO2: Factors!$J$44
Name CtoCO2: Factors!$J$44
Name CtoCO2: Factors!$J$44
Name CtoCO2: Factors!$J$44
Name CtoCO2: Factors!$J$44
Name CtoCO2: Factors!$J$44
Name CtoCO2: Factors!$J$44
Name CtoCO2: Factors!$J$44
Name CtoCO2: Factors!$J$44
Name CtoCO2: Factors!$J$44
Name CtoCO2: Factors!$J$44
Name CtoCO2: Factors!$J$44
Name CtoCO2: Factors!$J$44
Name CtoCO2: Factors!$J$44
Name CtoCO2: Factors!$J$44
Name CtoCO2: Factors!$J$44
Name DaysToYear: Factors!$J$51
Name gtokt: [4]Factors!$B$7
Name gtokt: [4]Factors!$B$7
Name GWPCH4: Factors!$J$46
Name GWPCH4: Factors!$J$46
Name GWPCH4: Factors!$J$46
Name GWPCH4: Factors!$J$46
Name GWPN2O: Factors!$J$50
Name GWPN2O: Factors!$J$50

Sheet Introduction
B2: CO2 Emissions from Fossil Fuel Combustion in the United States
B3: Purpose: | D3: Calculate CO2 emissions from fossil fuel combustion for Inventory of U.S. Greenhouse Gases
B4: Inventory Year: | D4: 1990-2022
B5: Source Category: | D5: Fossil Fuel Combustion (CRF Source Category 1A)
B6: Data Sources: | D6: Energy Information Administration's (EIA) Monthly Energy Review (November 2023); Non-Energy Uses of Fuels emission estimates; International Bunker Fuel emission estimates; EIA's U.S. Territories fuel consumption data; EPA's IndCalcs emission estimates; Aluminum emission estimates; Biomass emission estimates; Mobile Combustion emission estimates; Stationary Combustion emission estimates; Synthetic Natural Gas adjustment data; 2006 IPCC Guidelines; Revised 1996 IPCC Guidelines.
B7: Prepared By: | D7: Fiona Wissell, Emily Carr, Georgia Kerkezis, and Isabella Scornaienchi, ICF
B8: Prepared For: | D8: U.S. Environmental Protection Agency (EPA)
B9: Date: | D9: 45272
B13: Formatting Legend
C14: Data input cells
C15: Hardcoded cells
B16: Red text | C16: Proxy values

Sheet TOC
B2: Worksheet | D2: Contents
B3: CRF Reporter Input | D3: CRF Reporter data input tab for CO2 from Fossil Fuel Combustion emission estimates
B4: InvDB | D4: CO2 from Fossil Fuel Combustion estimates for the Inventory database
B5: Summary Table | D5: Summary tables for CO2 emissions from fossil fuel combustion
B6: 2021FR Comparison | D6: Comparison to previous cycle's emission estimates (Background Calculation Worksheet)
B7: 2021BY Comparison | D7: Comparison to previous year's emission estimates (Background Calculation Worksheet)
B8: Yearly Change | D8: Annual change in CO2 emissions from fossil fuel combustion (Background Calculation Worksheet)
B9: Consumption (E) | D9: Fossil fuel consumption for energy uses (Background Calculation Worksheet)
B10: Consumption (E + non-E) | D10: Fossil fuel consumption for energy and non-energy uses (Background Calculation Worksheet)
B11: Consumption Input | D11: Fuel consumption data by fuel type and sector used for calculating CO2 emissions from fossil fuel combustion (Background Calculation Worksheet)
B12: Corrections | D12: Adjustments made to fuel consumption estimates prior to calculating emissions (Background Calculation Worksheet)
B13: 1990 | D13: Emissions calculations for 1990 (Background Calculation Worksheet)
B14: 1991 | D14: Emissions calculations for 1991 (Background Calculation Worksheet)
B15: 1992 | D15: Emissions calculations for 1992 (Background Calculation Worksheet)
B16: 1993 | D16: Emissions calculations for 1993 (Background Calculation Worksheet)
B17: 1994 | D17: Emissions calculations for 1994 (Background Calculation Worksheet)
B18: 1995 | D18: Emissions calculations for 1995 (Background Calculation Worksheet)
B19: 1996 | D19: Emissions calculations for 1996 (Background Calculation Worksheet)
B20: 1997 | D20: Emissions calculations for 1997 (Background Calculation Worksheet)
B21: 1998 | D21: Emissions calculations for 1998 (Background Calculation Worksheet)
B22: 1999 | D22: Emissions calculations for 1999 (Background Calculation Worksheet)
B23: 2000 | D23: Emissions calculations for 2000 (Background Calculation Worksheet)
B24: 2001 | D24: Emissions calculations for 2001 (Background Calculation Worksheet)
... B45: 2022 | D45: Emissions calculations for the current Inventory year
B46: US Territories | D46: Emissions from U.S. Territories
B47: International Bunker Fuels | D47: Emissions from International Bunker Fuels
B48: Factors | D48: Emission factors used for calculating CO2 emissions from fossil fuel combustion (Background Calculation Worksheet)
B49: Non-Energy use | D49: Adjustments made to account for non-energy uses of fuels (Background Calculation Worksheet)
B50: Geothermal | D50: Emissions from Geothermal (Background Calculation Worksheet)
B51: Inventory Table | D51: Summary tables used in Inventory text (Background Calculation Worksheet)
B52: OUTPUT to INDCALC | D52: CO2 from fossil fuel combustion estimates used in EPA's IndCalcs spreadsheets (Background Calculation Worksheet)
B53: OUTPUT to MOBILE | D53: CO2 from fossil fuel combustion estimates used in mobile combustion calculations (Background Calculation Worksheet)
B54: Consumption Input Diff. | D54: Comparison to previous year's fuel consumption estimates (Background Calculation Worksheet)
B55: Electricity Distributed | D55: Apportions electricity related emissions to the 4 end-use sectors, based on their relative electricity consumption (Background Calculation Worksheet)
B56: Gas-Level Emissions | D56: Summarizes CO2, CH4, and N2O emissions from fossil fuel combustion (Background Calculation Worksheet)

Sheet CRF Reporter Input
A1: Source Lead Input for CRF Reporter
A2: 1.AA Fuel Combustion - Sectoral approach and 1.AD Feedstocks, reductants and other non-energy use of fuels | J2: Updated: | K2: 45195
T3: IE | U3: Yes
B4: The CRF Reporter is a separate, required component of the submission to the UNFCCC. The Inventory compilers are tasked with organizing and reporting out the data on this tab. We need your help to ensure that the CRFs represent your Inventory data, methods, and assumptions. The CRF forms the basis of the U.S.'s UNFCCC review and thus may get more scrutiny than the Inventory report itself. This tab is populated based on your data. We recommend you complete this tab as you are compiling the Inventory estimates. | O4: Required input for CRF | T4: NE | U4: No
O5: Instructions | T5: NA
T6: NO
T7: C
A9: Step ① - Update and Review Inputs to CRF Reporter
A14: UID | B14: CRF Input | C14: Alternative Variable Name | D14: Gas | E14: Unit | F14: 1990 | G14: 1991 | H14: 1992 | I14: 1993 | J14: 1994 | K14: 1995 | L14: 1996 | M14: 1997 | N14: 1998 | O14: 1999 | P14: 2000 | Q14: 2001 | R14: 2002 | S14: 2003 | T14: 2004 | U14: 2005 | V14: 2006 | W14: 2007 | X14: 2008 | Y14: 2009 | Z14: 2010 | AA14: 2011 | AB14: 2012 | AC14: 2013 | AD14: 2014 | AE14: 2015 | AF14: 2016 | AG14: 2017 | AH14: 2018 | AI14: 2019 | AJ14: 2020 | AK14: 2021 | AL14: 2022 | AM14: "NE" and "IE" Comment | AN14: If IE, where reported?
A15: 1.AA.1.A.1.a.i Energy Industries: Public Electricity and Heat Production: Electricity Generation
A16: 1.AA.1.A.1.a.i Liquid Fuels
A17: 83B2DB58-13EC-4B27-B374-781CA0FE13BA | B17: Fuel Consumption | E17: TJ | F17: ='1990'!$R$18*1055.05585262 -> 1360423.8 | G17: ='1991'!$R$18*1055.05585262 -> 1264232.3 | H17: ='1992'!$R$18*1055.05585262 -> 1045251.2 | I17: ='1993'!$R$18*1055.05585262 -> 1185660.2 | J17: ='1994'!$R$18*1055.05585262 -> 1116966.5 | K17: ='1995'!$R$18*1055.05585262 -> 796044.92 | L17: ='1996'!$R$18*1055.05585262 -> 862257.06 | M17: ='1997'!$R$18*1055.05585262 -> 977726.59 | N17: ='1998'!$R$18*1055.05585262 -> 1378003.2 | O17: ='1999'!$R$18*1055.05585262 -> 1277890 | P17: ='2000'!$R$18*1055.05585262 -> 1207131.6 | Q17: ='2001'!$R$18*1055.05585262 -> 1346648 | R17: ='2002'!$R$18*1055.05585262 -> 1014102.8 | S17: ='2003'!$R$18*1055.05585262 -> 1271151.3 | T17: ='2004'!$R$18*1055.05585262 -> 1267118.9 | U17: ='2005'!$R$18*1055.05585262 -> 1289345.8 | V17: ='2006'!$R$18*1055.05585262 -> 672026.27 | W17: ='2007'!$R$18*1055.05585262 -> 683497.89 | X17: ='2008'!$R$18*1055.05585262 -> 484625.14 | Y17: ='2009'!$R$18*1055.05585262 -> 403422.76 | Z17: ='2010'!$R$18*1055.05585262 -> 390714.61 | AA17: ='2011'!$R$18*1055.05585262 -> 311283.68 | AB17: ='2012'!$R$18*1055.05585262 -> 225998.24 | AC17: ='2013'!$R$18*1055.05585262 -> 269211.22 | AD17: ='2014'!$R$18*1055.05585262 -> 311736.3 | AE17: ='2015'!$R$18*1055.05585262 -> 291158.49 | AF17: ='2016'!$R$18*1055.05585262 -> 257327.07 | AG17: ='2017'!$R$18*1055.05585262 -> 229708.87 | AH17: ='2018'!$R$18*1055.05585262 -> 274683.79 | AI17: ='2019'!$R$18*1055.05585262 -> 198968.76 | AJ17: ='2020'!$R$18*1055.05585262 -> 194549.13 | AK17: ='2021'!$R$18*1055.05585262 -> 216301.22 | AL17: ='2022'!$R$18*1055.05585262 -> 257289.09
A18: D8064894-8E9F-4CD6-A941-F90E56784D8D | B18: Calorific value | F18: GCV | G18: GCV | H18: GCV | I18: GCV | J18: GCV | K18: GCV | L18: GCV | M18: GCV | N18: GCV | O18: GCV | P18: GCV | Q18: GCV | R18: GCV | S18: GCV | T18: GCV | U18: GCV | V18: GCV | W18: GCV | X18: GCV | Y18: GCV | Z18: GCV | AA18: GCV | AB18: GCV | AC18: GCV | AD18: GCV | AE18: GCV | AF18: GCV | AG18: GCV | AH18: GCV | AI18: GCV | AJ18: GCV | AK18: GCV | AL18: GCV
A19: AA89486D-1625-44E9-81F2-30D53DFB696D | B19: Emissions | D19: CO2 | E19: kt | F19: =('Summary Table'!C26*1000) -> 97538.491 | G19: =('Summary Table'!D26*1000) -> 90678.662 | H19: =('Summary Table'!E26*1000) -> 75527.743 | I19: =('Summary Table'!F26*1000) -> 86415.413 | J19: =('Summary Table'!G26*1000) -> 81246.85 | K19: =('Summary Table'!H26*1000) -> 58711.775 | L19: =('Summary Table'!I26*1000) -> 63396.293 | M19: =('Summary Table'!J26*1000) -> 72207.404 | ... AL19: =('Summary Table'!AI26*1000) -> 20522.249
A20: 1326B4AF-4523-41D5-9B8C-533B5AEBEA7C | B20: Amount captured | D20: CO2 | E20: kt | F20: NA | G20: NA | H20: NA | I20: NA | J20: NA | K20: NA | L20: NA | M20: NA | N20: NA | O20: NA | P20: NA | Q20: NA | R20: NA | S20: NA | T20: NA | U20: NA | V20: NA | W20: NA | X20: NA | Y20: NA | Z20: NA | AA20: NA | AB20: NA | AC20: NA | AD20: NA | AE20: NA | AF20: NA | AG20: NA | AH20: NA | AI20: NA | AJ20: NA | AK20: NA | AL20: NA
A21: FDC84FC0-D144-46AD-AA6E-86015DE27968 | B21: Documentation box
A22: 1.AA.1.A.1.a.i Solid Fuels
A23: B749F72A-0FE8-4E17-8EBC-3F74FE380CBA | B23: Fuel Consumption | E23: TJ | F23: ='1990'!$R$8*1055.05585262 -> 17156213 | G23: ='1991'!$R$8*1055.05585262 -> 17144351 | H23: ='1992'!$R$8*1055.05585262 -> 17372122 | I23: ='1993'!$R$8*1055.05585262 -> 18142663 | J23: ='1994'!$R$8*1055.05585262 -> 18211187 | K23: ='1995'!$R$8*1055.05585262 -> 18427906 | L23: ='1996'!$R$8*1055.05585262 -> 19443653 | M23: ='1997'!$R$8*1055.05585262 -> 19945343 | N23: ='1998'!$R$8*1055.05585262 -> 20273618 | O23: ='1999'!$R$8*1055.05585262 -> 20340936 | P23: ='2000'!$R$8*1055.05585262 -> 21333410 | Q23: ='2001'!$R$8*1055.05585262 -> 20693520 | R23: ='2002'!$R$8*1055.05585262 -> 20871939 | S23: ='2003'!$R$8*1055.05585262 -> 21296031 | T23: ='2004'!$R$8*1055.05585262 -> 21422946 | U23: ='2005'!$R$8*1055.05585262 -> 21878947 | V23: ='2006'!$R$8*1055.05585262 -> 21588429 | W23: ='2007'!$R$8*1055.05585262 -> 21953309 | X23: ='2008'!$R$8*1055.05585262 -> 21642313 | Y23: ='2009'!$R$8*1055.05585262 -> 19228743 | Z23: ='2010'!$R$8*1055.05585262 -> 20186864 | AA23: ='2011'!$R$8*1055.05585262 -> 19028117 | AB23: ='2012'!$R$8*1055.05585262 -> 16692300 | AC23: ='2013'!$R$8*1055.05585262 -> 17356259 | AD23: ='2014'!$R$8*1055.05585262 -> 17331825 | AE23: ='2015'!$R$8*1055.05585262 -> 14916643 | AF23: ='2016'!$R$8*1055.05585262 -> 13711879 | AG23: ='2017'!$R$8*1055.05585262 -> 13317161 | AH23: ='2018'!$R$8*1055.05585262 -> 12716543 | AI23: ='2019'!$R$8*1055.05585262 -> 10741800 | AJ23: ='2020'!$R$8*1055.05585262 -> 8682353.2 | AK23: ='2021'!$R$8*1055.05585262 -> 10020574 | AL23: ='2022'!$R$8*1055.05585262 -> 9374689.3
A24: 42425060-D7CF-4C1F-AE75-5C24167A8D3F | B24: Calorific value | F24: GCV | G24: GCV | H24: GCV | I24: GCV | J24: GCV | K24: GCV | L24: GCV | M24: GCV | N24: GCV | O24: GCV | P24: GCV | Q24: GCV | R24: GCV | S24: GCV | T24: GCV | U24: GCV | V24: GCV | W24: GCV | X24: GCV | Y24: GCV | Z24: GCV | AA24: GCV | AB24: GCV | AC24: GCV | AD24: GCV | AE24: GCV | AF24: GCV | AG24: GCV | AH24: GCV | AI24: GCV | AJ24: GCV | AK24: GCV | AL24: GCV
A25: 09383287-D40C-486E-AC77-9D5A5603A277 | B25: Emissions | D25: CO2 | E25: kt | F25: =('Summary Table'!C12*1000) -> 1546513.9 | G25: =('Summary Table'!D12*1000) -> 1547174.5 | H25: =('Summary Table'!E12*1000) -> 1568541.5 | I25: =('Summary Table'!F12*1000) -> 1631618.8 | J25: =('Summary Table'!G12*1000) -> 1637852.8 | K25: =('Summary Table'!H12*1000) -> 1659860.9 | L25: =('Summary Table'!I12*1000) -> 1751523.4 | M25: =('Summary Table'!J12*1000) -> 1796018.9 | ... AL25: =('Summary Table'!AI12*1000) -> 851472.06
A26: E7A0CF0A-A523-4997-B846-A44D2711E895 | B26: Amount captured | D26: CO2 | E26: kt | F26: NA | G26: NA | H26: NA | I26: NA | J26: NA | K26: NA | L26: NA | M26: NA | N26: NA | O26: NA | P26: NA | Q26: NA | R26: NA | S26: NA | T26: NA | U26: NA | V26: NA | W26: NA | X26: NA | Y26: NA | Z26: NA | AA26: NA | AB26: NA | AC26: NA | AD26: NA | AE26: NA | AF26: NA | AG26: NA | AH26: NA | AI26: NA | AJ26: NA | AK26: NA | AL26: NA
A27: C75783E3-9C29-48C0-A735-453BE5F9FB45 | B27: Documentation box
A28: 1.AA.1.A.1.a.i Gaseous Fuels
A29: 956A7BFF-ACB7-4333-898F-3BAEEB8396D0 | B29: Fuel Consumption | E29: TJ | F29: ='1990'!$R$17*1055.05585262 -> 3490692.4 | G29: ='1991'!$R$17*1055.05585262 -> 3563302.4 | H29: ='1992'!$R$17*1055.05585262 -> 3704830.7 | I29: ='1993'!$R$17*1055.05585262 -> 3732261.1 | J29: ='1994'!$R$17*1055.05585262 -> 4196272.6 | K29: ='1995'!$R$17*1055.05585262 -> 4538819.7 | L29: ='1996'!$R$17*1055.05585262 -> 4075099.4 | M29: ='1997'!$R$17*1055.05585262 -> 4352645.6 | N29: ='1998'!$R$17*1055.05585262 -> 4932280.6 | O29: ='1999'!$R$17*1055.05585262 -> 5172039.9 | P29: ='2000'!$R$17*1055.05585262 -> 5584806.3 | Q29: ='2001'!$R$17*1055.05585262 -> 5758601.4 | R29: ='2002'!$R$17*1055.05585262 -> 6084308.8 | S29: ='2003'!$R$17*1055.05585262 -> 5535085.7 | T29: ='2004'!$R$17*1055.05585262 -> 5902968.9 | U29: ='2005'!$R$17*1055.05585262 -> 6345684.1 | V29: ='2006'!$R$17*1055.05585262 -> 6726127.7 | W29: ='2007'!$R$17*1055.05585262 -> 7390913.1 | X29: ='2008'!$R$17*1055.05585262 -> 7204896.2 | Y29: ='2009'!$R$17*1055.05585262 -> 7409013.7 | Z29: ='2010'!$R$17*1055.05585262 -> 7942081.7 | AA29: ='2011'!$R$17*1055.05585262 -> 8136807 | AB29: ='2012'!$R$17*1055.05585262 -> 9798085.3 | AC29: ='2013'!$R$17*1055.05585262 -> 8837415.8 | AD29: ='2014'!$R$17*1055.05585262 -> 8822040.5 | AE29: ='2015'!$R$17*1055.05585262 -> 10472969 | AF29: ='2016'!$R$17*1055.05585262 -> 10868458 | AG29: ='2017'!$R$17*1055.05585262 -> 10081277 | AH29: ='2018'!$R$17*1055.05585262 -> 11522801 | AI29: ='2019'!$R$17*1055.05585262 -> 12300262 | AJ29: ='2020'!$R$17*1055.05585262 -> 12660424 | AK29: ='2021'!$R$17*1055.05585262 -> 12220274 | AL29: ='2022'!$R$17*1055.05585262 -> 13145140
A30: 1406EE50-C21B-4E07-A176-6CF1F5463938 | B30: Calorific value | F30: GCV | G30: GCV | H30: GCV | I30: GCV | J30: GCV | K30: GCV | L30: GCV | M30: GCV | N30: GCV | O30: GCV | P30: GCV | Q30: GCV | R30: GCV | S30: GCV | T30: GCV | U30: GCV | V30: GCV | W30: GCV | X30: GCV | Y30: GCV | Z30: GCV | AA30: GCV | AB30: GCV | AC30: GCV | AD30: GCV | AE30: GCV | AF30: GCV | AG30: GCV | AH30: GCV | AI30: GCV | AJ30: GCV | AK30: GCV | AL30: GCV
A31: E46A0E1A-9B27-4049-AA56-E2B2204CD263 | B31: Emissions | D31: CO2 | E31: kt | F31: =('Summary Table'!C19*1000) -> 175360.04 | G31: =('Summary Table'!D19*1000) -> 178966.42 | H31: =('Summary Table'!E19*1000) -> 186074.66 | I31: =('Summary Table'!F19*1000) -> 187582.35 | J31: =('Summary Table'!G19*1000) -> 210854.62 | K31: =('Summary Table'!H19*1000) -> 228172.66 | L31: =('Summary Table'!I19*1000) -> 204860.81 | M31: =('Summary Table'!J19*1000) -> 218813.43 | ... AL31: =('Summary Table'!AI19*1000) -> 659305.21
A32: 9593053F-47FC-4D5D-962C-5C6BBB3C97D1 | B32: Amount captured | D32: CO2 | E32: kt | F32: NA | G32: NA | H32: NA | I32: NA | J32: NA | K32: NA | L32: NA | M32: NA | N32: NA | O32: NA | P32: NA | Q32: NA | R32: NA | S32: NA | T32: NA | U32: NA | V32: NA | W32: NA | X32: NA | Y32: NA | Z32: NA | AA32: NA | AB32: NA | AC32: NA | AD32: NA | AE32: NA | AF32: NA | AG32: NA | AH32: NA | AI32: NA | AJ32: NA | AK32: NA | AL32: NA
A33: E5D7A95E-512E-4D32-9B4C-F8C1611994D5 | B33: Documentation box
A34: 1.AA.1.A.1.a.i Other Fossil Fuels
A35: CFEDB877-B634-46AA-9EC6-3125CAB769BE | B35: Fuel Consumption | E35: TJ | F35: =('1990'!$R$42*1055.05585262) -> 55561.07 | G35: =('1991'!$R$42*1055.05585262) -> 57476.814 | H35: =('1992'!$R$42*1055.05585262) -> 58094.253 | I35: =('1993'!$R$42*1055.05585262) -> 60436.326 | J35: =('1994'!$R$42*1055.05585262) -> 55925.311 | K35: =('1995'!$R$42*1055.05585262) -> 48159.728 | L35: =('1996'!$R$42*1055.05585262) -> 51581.121 | M35: =('1997'!$R$42*1055.05585262) -> 53011.767 | N35: =('1998'!$R$42*1055.05585262) -> 53183.899 | O35: =('1999'!$R$42*1055.05585262) -> 53375.031 | P35: =('2000'!$R$42*1055.05585262) -> 50733.263 | Q35: =('2001'!$R$42*1055.05585262) -> 49463.758 | R35: =('2002'!$R$42*1055.05585262) -> 52166.55 | S35: =('2003'!$R$42*1055.05585262) -> 51925.077 | T35: =('2004'!$R$42*1055.05585262) -> 53317.295 | U35: =('2005'!$R$42*1055.05585262) -> 52888.087 | V35: =('2006'!$R$42*1055.05585262) -> 52442.727 | W35: =('2007'!$R$42*1055.05585262) -> 52691.78 | X35: =('2008'!$R$42*1055.05585262) -> 53421.698 | Y35: =('2009'!$R$42*1055.05585262) -> 54028.926 | Z35: =('2010'!$R$42*1055.05585262) -> 54786.893 | AA35: =('2011'!$R$42*1055.05585262) -> 55135.556 | AB35: =('2012'!$R$42*1055.05585262) -> 56022.407 | AC35: =('2013'!$R$42*1055.05585262) -> 56786.469 | AD35: =('2014'!$R$42*1055.05585262) -> 57154.615 | AE35: =('2015'!$R$42*1055.05585262) -> 57300.891 | AF35: =('2016'!$R$42*1055.05585262) -> 56970.54 | AG35: =('2017'!$R$42*1055.05585262) -> 57334.007 | AH35: =('2018'!$R$42*1055.05585262) -> 57479.296 | AI35: =('2019'!$R$42*1055.05585262) -> 55699.469 | AJ35: =('2020'!$R$42*1055.05585262) -> 57200.535 | AK35: =('2021'!$R$42*1055.05585262) -> 57506.774 | AL35: =('2022'!$R$42*1055.05585262) -> 57910.541
A36: AF3B8BA2-7A64-4F64-BD16-FB173A68F027 | B36: Calorific value | F36: GCV | G36: GCV | H36: GCV | I36: GCV | J36: GCV | K36: GCV | L36: GCV | M36: GCV | N36: GCV | O36: GCV | P36: GCV | Q36: GCV | R36: GCV | S36: GCV | T36: GCV | U36: GCV | V36: GCV | W36: GCV | X36: GCV | Y36: GCV | Z36: GCV | AA36: GCV | AB36: GCV | AC36: GCV | AD36: GCV | AE36: GCV | AF36: GCV | AG36: GCV | AH36: GCV | AI36: GCV | AJ36: GCV | AK36: GCV | AL36: GCV
A37: A19CCF55-320D-4448-9F81-E0FCC82712C7 | B37: Emissions | D37: CO2 | E37: kt | F37: ='Summary Table'!C28*1000 -> 538.19392 | G37: ='Summary Table'!D28*1000 -> 539.13329 | H37: ='Summary Table'!E28*1000 -> 544.07239 | I37: ='Summary Table'!F28*1000 -> 555.49804 | J37: ='Summary Table'!G28*1000 -> 514.16615 | K37: ='Summary Table'!H28*1000 -> 427.8974 | L37: ='Summary Table'!I28*1000 -> 462.47774 | M37: ='Summary Table'!J28*1000 -> 480.08445 | ... AL37: ='Summary Table'!AI28*1000 -> 380.55713
A38: 609F1D6D-269A-4E5A-84D8-C5B10647984C | B38: Amount captured | D38: CO2 | E38: kt | F38: NA | G38: NA | H38: NA | I38: NA | J38: NA | K38: NA | L38: NA | M38: NA | N38: NA | O38: NA | P38: NA | Q38: NA | R38: NA | S38: NA | T38: NA | U38: NA | V38: NA | W38: NA | X38: NA | Y38: NA | Z38: NA | AA38: NA | AB38: NA | AC38: NA | AD38: NA | AE38: NA | AF38: NA | AG38: NA | AH38: NA | AI38: NA | AJ38: NA | AK38: NA | AL38: NA
A39: 03962A08-B6B1-4187-A49B-5BB732482AB5 | B39: Documentation box | F39: 1.A.1.a.i Energy Industries\Public Electricity and Heat Production\Electricity Generation: Other fuels includes geothermal consumption and emissions. | G39: 1.A.1.a.i Energy Industries\Public Electricity and Heat Production\Electricity Generation: Other fuels includes geothermal consumption and emissions. | H39: 1.A.1.a.i Energy Industries\Public Electricity and Heat Production\Electricity Generation: Other fuels includes geothermal consumption and emissions. | I39: 1.A.1.a.i Energy Industries\Public Electricity and Heat Production\Electricity Generation: Other fuels includes geothermal consumption and emissions. | J39: 1.A.1.a.i Energy Industries\Public Electricity and Heat Production\Electricity Generation: Other fuels includes geothermal consumption and emissions. | K39: 1.A.1.a.i Energy Industries\Public Electricity and Heat Production\Electricity Generation: Other fuels includes geothermal consumption and emissions. | L39: 1.A.1.a.i Energy Industries\Public Electricity and Heat Production\Electricity Generation: Other fuels includes geothermal consumption and emissions. | M39: 1.A.1.a.i Energy Industries\Public Electricity and Heat Production\Electricity Generation: Other fuels includes geothermal consumption and emissions. | N39: 1.A.1.a.i Energy Industries\Public Electricity and Heat Production\Electricity Generation: Other fuels includes geothermal consumption and emissions. | O39: 1.A.1.a.i Energy Industries\Public Electricity and Heat Production\Electricity Generation: Other fuels includes geothermal consumption and emissions. | P39: 1.A.1.a.i Energy Industries\Public Electricity and Heat Production\Electricity Generation: Other fuels includes geothermal consumption and emissions. | Q39: 1.A.1.a.i Energy Industries\Public Electricity and Heat Production\Electricity Generation: Other fuels includes geothermal consumption and emissions. | R39: 1.A.1.a.i Energy Industries\Public Electricity and Heat Production\Electricity Generation: Other fuels includes geothermal consumption and emissions. | S39: 1.A.1.a.i Energy Industries\Public Electricity and Heat Production\Electricity Generation: Other fuels includes geothermal consumption and emissions. | T39: 1.A.1.a.i Energy Industries\Public Electricity and Heat Production\Electricity Generation: Other fuels includes geothermal consumption and emissions. | U39: 1.A.1.a.i Energy Industries\Public Electricity and Heat Production\Electricity Generation: Other fuels includes geothermal consumption and emissions. | V39: 1.A.1.a.i Energy Industries\Public Electricity and Heat Production\Electricity Generation: Other fuels includes geothermal consumption and emissions. | W39: 1.A.1.a.i Energy Industries\Public Electricity and Heat Production\Electricity Generation: Other fuels includes geothermal consumption and emissions. | X39: 1.A.1.a.i Energy Industries\Public Electricity and Heat Production\Electricity Generation: Other fuels includes geothermal consumption and emissions. | Y39: 1.A.1.a.i Energy Industries\Public Electricity and Heat Production\Electricity Generation: Other fuels includes geothermal consumption and emissions. | Z39: 1.A.1.a.i Energy Industries\Public Electricity and Heat Production\Electricity Generation: Other fuels includes geothermal consumption and emissions. | AA39: 1.A.1.a.i Energy Industries\Public Electricity and Heat Production\Electricity Generation: Other fuels includes geothermal consumption and emissions. | AB39: 1.A.1.a.i Energy Industries\Public Electricity and Heat Production\Electricity Generation: Other fuels includes geothermal consumption and emissions. | AC39: 1.A.1.a.i Energy Industries\Public Electricity and Heat Production\Electricity Generation: Other fuels includes geothermal consumption and emissions. | AD39: 1.A.1.a.i Energy Industries\Public Electricity and Heat Production\Electricity Generation: Other fuels includes geothermal consumption and emissions. | AE39: 1.A.1.a.i Energy Industries\Public Electricity and Heat Production\Electricity Generation: Other fuels includes geothermal consumption and emissions. | AF39: 1.A.1.a.i Energy Industries\Public Electricity and Heat Production\Electricity Generation: Other fuels includes geothermal consumption and emissions. | AG39: 1.A.1.a.i Energy Industries\Public Electricity and Heat Production\Electricity Generation: Other fuels includes geothermal consumption and emissions. | AH39: 1.A.1.a.i Energy Industries\Public Electricity and Heat Production\Electricity Generation: Other fuels includes geothermal consumption and emissions. | AI39: 1.A.1.a.i Energy Industries\Public Electricity and Heat Production\Electricity Generation: Other fuels includes geothermal consumption and emissions. | AJ39: 1.A.1.a.i Energy Industries\Public Electricity and Heat Production\Electricity Generation: Other fuels includes geothermal consumption and emissions. | AK39: 1.A.1.a.i Energy Industries\Public Electricity and Heat Production\Electricity Generation: Other fuels includes geothermal consumption and emissions. | AL39: 1.A.1.a.i Energy Industries\Public Electricity and Heat Production\Electricity Generation: Other fuels includes geothermal consumption and emissions.
A40: 1.AA.1.A.1.a.i Peat
A41: 162EBEF3-379B-409A-AFB3-D94B1AE203DD | B41: Fuel Consumption | E41: TJ | F41: NO | G41: NO | H41: NO | I41: NO | J41: NO | K41: NO | L41: NO | M41: NO | N41: NO | O41: NO | P41: NO | Q41: NO | R41: NO | S41: NO | T41: NO | U41: NO | V41: NO | W41: NO | X41: NO | Y41: NO | Z41: NO | AA41: NO | AB41: NO | AC41: NO | AD41: NO | AE41: NO | AF41: NO | AG41: NO | AH41: NO | AI41: NO | AJ41: NO | AK41: NO | AL41: NO
A42: 5EC58608-EE91-4DC0-AFA9-840B56D41802 | B42: Calorific value | F42: GCV | G42: GCV | H42: GCV | I42: GCV | J42: GCV | K42: GCV | L42: GCV | M42: GCV | N42: GCV | O42: GCV | P42: GCV | Q42: GCV | R42: GCV | S42: GCV | T42: GCV | U42: GCV | V42: GCV | W42: GCV | X42: GCV | Y42: GCV | Z42: GCV | AA42: GCV | AB42: GCV | AC42: GCV | AD42: GCV | AE42: GCV | AF42: GCV | AG42: GCV | AH42: GCV | AI42: GCV | AJ42: GCV | AK42: GCV | AL42: GCV
A43: CCA16091-DDBD-4BD3-BF2E-3A06A7CA12DB | B43: Emissions | D43: CO2 | E43: kt | F43: NO | G43: NO | H43: NO | I43: NO | J43: NO | K43: NO | L43: NO | M43: NO | N43: NO | O43: NO | P43: NO | Q43: NO | R43: NO | S43: NO | T43: NO | U43: NO | V43: NO | W43: NO | X43: NO | Y43: NO | Z43: NO | AA43: NO | AB43: NO | AC43: NO | AD43: NO | AE43: NO | AF43: NO | AG43: NO | AH43: NO | AI43: NO | AJ43: NO | AK43: NO | AL43: NO
A44: DC0206BD-D9B0-4D94-AE12-36990568E589 | B44: Amount captured | D44: CO2 | E44: kt | F44: NO | G44: NO | H44: NO | I44: NO | J44: NO | K44: NO | L44: NO | M44: NO | N44: NO | O44: NO | P44: NO | Q44: NO | R44: NO | S44: NO | T44: NO | U44: NO | V44: NO | W44: NO | X44: NO | Y44: NO | Z44: NO | AA44: NO | AB44: NO | AC44: NO | AD44: NO | AE44: NO | AF44: NO | AG44: NO | AH44: NO | AI44: NO | AJ44: NO | AK44: NO | AL44: NO
A45: 4BBEA713-295E-413C-AB31-23D4549E3F86 | B45: Documentation box
...

Sheet InvDB
A1: Inventory Database Input Template
A3: Unified InvDB Template Instructions: | J3: Conversion Factors
A4: Columns starting with 1990 (e.g. U) thru latest year should reflect annual GHG estimates for 1990 through the current year. Please correct underlying formulas if source data cells were shifted from previous cycles. If revisions to the sector, subsector, etc. columns are needed, or additional rows are needed please contact desai.mausami@epa.gov to ensure InvDB reference data is updated accordingly. Use notation keys in data cells where the GHG estimate is not a true zero, e.g., IE (Included Elsewhere); NO (Not Occuring); NE (Not Estimated), etc. as applied for reporting data in the UN common reporting tables. | J4: KT per Tg | K4: 1000
J5: Neg | K5: -1
J6: as needed
A8: Source/Sink Category | C8: CO2 From Fossil Fuel Combustion
A9: Author Name | C9: Vincent Camobreco
A10: Author Email | C10: Camobreco.Vincent@EPA.gov
A11: Publication Year | C11: 2024
A12: Notes
BB14: Note: Y2023 - Y2030 columns will not be active in Publication Year 2024 but should not be used
A16: Data Type | B16: Sector | C16: Subsector | D16: Category | E16: Subcategory1 | F16: Subcategory2 | G16: Subcategory3 | H16: Subcategory4 | I16: Subcategory5 | J16: Carbon Pool | K16: Fuel1 | L16: Fuel2 | M16: GeoRef | N16: Exclude | O16: CRT Code | P16: ID | Q16: Sensitive (Y or N) | R16: Units | S16: GHG | T16: GWP | U16: 1990 | V16: 1991 | W16: 1992 | X16: 1993 | Y16: 1994 | Z16: 1995 | AA16: 1996 | AB16: 1997 | AC16: 1998 | AD16: 1999 | AE16: 2000 | AF16: 2001 | AG16: 2002 | AH16: 2003 | AI16: 2004 | AJ16: 2005 | AK16: 2006 | AL16: 2007 | AM16: 2008 | AN16: 2009 | AO16: 2010 | AP16: 2011 | AQ16: 2012 | AR16: 2013 | AS16: 2014 | AT16: 2015 | AU16: 2016 | AV16: 2017 | AW16: 2018 | AX16: 2019 | AY16: 2020 | AZ16: 2021 | BA16: 2022 | BB16: 2023 | BC16: 2024 | BD16: 2025 | BE16: 2026 | BF16: 2027 | BG16: 2028 | BH16: 2029 | BI16: 2030
A17: GHG | B17: Energy | C17: Fossil Fuel Combustion | D17: Residential | K17: Coal | M17: National | O17: 1.A.4.b. Residential | R17: Tg | S17: CO2 | T17: 1 | U17: =('Summary Table'!C8) -> 2.9876953 | V17: =('Summary Table'!D8) -> 2.4418666 | W17: =('Summary Table'!E8) -> 2.4754382 | X17: =('Summary Table'!F8) -> 2.4697528 | Y17: =('Summary Table'!G8) -> 1.9941821 | Z17: =('Summary Table'!H8) -> 1.6716718 | AA17: =('Summary Table'!I8) -> 1.5825802 | AB17: =('Summary Table'!J8) -> 1.5181716 | ... BA17: =('Summary Table'!AI8) -> 0
A18: GHG | B18: Energy | C18: Fossil Fuel Combustion | D18: Residential | K18: Natural Gas | M18: National | O18: 1.A.4.b. Residential | R18: Tg | S18: CO2 | T18: 1 | U18: =('Summary Table'!C15) -> 237.79751 | V18: =('Summary Table'!D15) -> 247.31637 | W18: =('Summary Table'!E15) -> 254.59498 | X18: =('Summary Table'!F15) -> 268.22933 | Y18: =('Summary Table'!G15) -> 262.94356 | Z18: =('Summary Table'!H15) -> 262.76571 | AA18: =('Summary Table'!I15) -> 283.99195 | AB18: =('Summary Table'!J15) -> 270.12382 | ... BA18: =('Summary Table'!AI15) -> 271.98682
A19: GHG | B19: Energy | C19: Fossil Fuel Combustion | D19: Residential | K19: Petroleum | M19: National | O19: 1.A.4.b. Residential | R19: Tg | S19: CO2 | T19: 1 | U19: =('Summary Table'!C22) -> 97.782412 | V19: =('Summary Table'!D22) -> 97.95217 | W19: =('Summary Table'!E22) -> 96.897398 | X19: =('Summary Table'!F22) -> 95.382683 | Y19: =('Summary Table'!G22) -> 92.10948 | Z19: =('Summary Table'!H22) -> 88.696195 | AA19: =('Summary Table'!I22) -> 97.899891 | AB19: =('Summary Table'!J22) -> 93.391359 | ... BA19: =('Summary Table'!AI22) -> 61.113012
A20: GHG | B20: Energy | C20: Fossil Fuel Combustion | D20: Commercial | K20: Coal | M20: National | O20: 1.A.4.a. Commercial/institutional | R20: Tg | S20: CO2 | T20: 1 | U20: =('Summary Table'!C9) -> 11.950781 | V20: =('Summary Table'!D9) -> 11.123952 | W20: =('Summary Table'!E9) -> 11.276792 | X20: =('Summary Table'!F9) -> 11.251192 | Y20: =('Summary Table'!G9) -> 11.30011 | Z20: =('Summary Table'!H9) -> 11.187394 | AA20: =('Summary Table'!I9) -> 11.605302 | AB20: =('Summary Table'!J9) -> 12.2835 | ... BA20: =('Summary Table'!AI9) -> 1.3881297
A21: GHG | B21: Energy | C21: Fossil Fuel Combustion | D21: Commercial | K21: Natural Gas | M21: National | O21: 1.A.4.a. Commercial/institutional | R21: Tg | S21: CO2 | T21: 1 | U21: =('Summary Table'!C16) -> 142.02474 | V21: =('Summary Table'!D16) -> 148.12843 | W21: =('Summary Table'!E16) -> 152.14428 | X21: =('Summary Table'!F16) -> 154.86031 | Y21: =('Summary Table'!G16) -> 157.02801 | Z21: =('Summary Table'!H16) -> 164.20846 | AA21: =('Summary Table'!I16) -> 171.12094 | AB21: =('Summary Table'!J16) -> 174.2504 | ... BA21: =('Summary Table'!AI16) -> 192.26242
A22: GHG | B22: Energy | C22: Fossil Fuel Combustion | D22: Commercial | K22: Petroleum | M22: National | O22: 1.A.4.a. Commercial/institutional | R22: Tg | S22: CO2 | T22: 1 | U22: =('Summary Table'!C23) -> 74.317009 | V22: =('Summary Table'!D23) -> 73.407834 | W22: =('Summary Table'!E23) -> 64.61673 | X22: =('Summary Table'!F23) -> 56.873975 | Y22: =('Summary Table'!G23) -> 56.369485 | Z22: =('Summary Table'!H23) -> 52.39124 | AA22: =('Summary Table'!I23) -> 54.832061 | AB22: =('Summary Table'!J23) -> 51.284956 | ... BA22: =('Summary Table'!AI23) -> 51.063465
A23: GHG | B23: Energy | C23: Fossil Fuel Combustion | D23: Industrial | K23: Coal | M23: National | O23: 1.A.2. Manufacturing industries and construction | R23: Tg | S23: CO2 | T23: 1 | U23: =('Summary Table'!C10) -> 157.83904 | V23: =('Summary Table'!D10) -> 154.63822 | W23: =('Summary Table'!E10) -> 150.27496 | X23: =('Summary Table'!F10) -> 152.54779 | Y23: =('Summary Table'!G10) -> 153.46903 | Z23: =('Summary Table'!H10) -> 147.21569 | AA23: =('Summary Table'!I10) -> 140.08938 | AB23: =('Summary Table'!J10) -> 140.23965 | ... BA23: =('Summary Table'!AI10) -> 42.659993
A24: GHG | B24: Energy | C24: Fossil Fuel Combustion | D24: Industrial | K24: Natural Gas | M24: National | O24: 1.A.2. Manufacturing industries and construction | R24: Tg | S24: CO2 | T24: 1 | U24: =('Summary Table'!C17) -> 407.44058 | V24: =('Summary Table'!D17) -> 413.59445 | W24: =('Summary Table'!E17) -> 429.30738 | X24: =('Summary Table'!F17) -> 436.9822 | Y24: =('Summary Table'!G17) -> 438.20865 | Z24: =('Summary Table'!H17) -> 461.468 | AA24: =('Summary Table'!I17) -> 477.22705 | AB24: =('Summary Table'!J17) -> 477.88613 | ... BA24: =('Summary Table'!AI17) -> 511.44589
A25: GHG | B25: Energy | C25: Fossil Fuel Combustion | D25: Industrial | K25: Petroleum | M25: National | O25: 1.A.2. Manufacturing industries and construction | R25: Tg | S25: CO2 | T25: 1 | U25: ='Summary Table'!C24 -> 305.86837 | V25: ='Summary Table'!D24 -> 292.78504 | W25: ='Summary Table'!E24 -> 301.03099 | X25: ='Summary Table'!F24 -> 293.10936 | Y25: ='Summary Table'!G24 -> 288.92185 | Z25: ='Summary Table'!H24 -> 291.98617 | AA25: ='Summary Table'!I24 -> 300.13888 | AB25: ='Summary Table'!J24 -> 294.15681 | ... BA25: ='Summary Table'!AI24 -> 221.75315
A26: GHG | B26: Energy | C26: Fossil Fuel Combustion | D26: Transportation | K26: Coal | M26: National | O26: 1.A.3. Transport | R26: Tg | S26: CO2 | T26: 1 | U26: =('Summary Table'!C11) -> NO | V26: =('Summary Table'!D11) -> NO | W26: =('Summary Table'!E11) -> NO | X26: =('Summary Table'!F11) -> NO | Y26: =('Summary Table'!G11) -> NO | Z26: =('Summary Table'!H11) -> NO | AA26: =('Summary Table'!I11) -> NO | AB26: =('Summary Table'!J11) -> NO | ... BA26: =('Summary Table'!AI11) -> NO
A27: GHG | B27: Energy | C27: Fossil Fuel Combustion | D27: Transportation | K27: Natural Gas | M27: National | O27: 1.A.3. Transport | R27: Tg | S27: CO2 | T27: 1 | U27: =('Summary Table'!C18) -> 36.000629 | V27: =('Summary Table'!D18) -> 32.870999 | W27: =('Summary Table'!E18) -> 32.223566 | X27: =('Summary Table'!F18) -> 34.154614 | Y27: =('Summary Table'!G18) -> 37.562805 | Z27: =('Summary Table'!H18) -> 38.39776 | AA27: =('Summary Table'!I18) -> 39.083768 | AB27: =('Summary Table'!J18) -> 41.387043 | ... BA27: =('Summary Table'!AI18) -> 70.161309
A28: GHG | B28: Energy | C28: Fossil Fuel Combustion | D28: Transportation | K28: Petroleum | M28: National | O28: 1.A.3. Transport | R28: Tg | S28: CO2 | T28: 1 | U28: ='Summary Table'!C25 -> 1432.9433 | V28: ='Summary Table'!D25 -> 1389.4564 | W28: ='Summary Table'!E25 -> 1445.4199 | X28: ='Summary Table'!F25 -> 1474.4524 | Y28: ='Summary Table'!G25 -> 1516.3845 | Z28: ='Summary Table'!H25 -> 1542.2801 | AA28: ='Summary Table'!I25 -> 1588.2793 | AB28: ='Summary Table'!J25 -> 1602.1285 | ... BA28: ='Summary Table'!AI25 -> 1710.6019
A29: GHG | B29: Energy | C29: Fossil Fuel Combustion | D29: Electricity Generation | K29: Coal | M29: National | O29: 1.A.1.a. Public electricity and heat production | R29: Tg | S29: CO2 | T29: 1 | U29: =('Summary Table'!C12) -> 1546.5139 | V29: =('Summary Table'!D12) -> 1547.1745 | W29: =('Summary Table'!E12) -> 1568.5415 | X29: =('Summary Table'!F12) -> 1631.6188 | Y29: =('Summary Table'!G12) -> 1637.8528 | Z29: =('Summary Table'!H12) -> 1659.8609 | AA29: =('Summary Table'!I12) -> 1751.5234 | AB29: =('Summary Table'!J12) -> 1796.0189 | ... BA29: =('Summary Table'!AI12) -> 851.47206
A30: GHG | B30: Energy | C30: Fossil Fuel Combustion | D30: Electricity Generation | K30: Natural Gas | M30: National | O30: 1.A.1.a. Public electricity and heat production | R30: Tg | S30: CO2 | T30: 1 | U30: =('Summary Table'!C19) -> 175.36004 | V30: =('Summary Table'!D19) -> 178.96642 | W30: =('Summary Table'!E19) -> 186.07466 | X30: =('Summary Table'!F19) -> 187.58235 | Y30: =('Summary Table'!G19) -> 210.85462 | Z30: =('Summary Table'!H19) -> 228.17266 | AA30: =('Summary Table'!I19) -> 204.86081 | AB30: =('Summary Table'!J19) -> 218.81343 | ... BA30: =('Summary Table'!AI19) -> 659.30521
A31: GHG | B31: Energy | C31: Fossil Fuel Combustion | D31: Electricity Generation | K31: Petroleum | M31: National | O31: 1.A.1.a. Public electricity and heat production | R31: Tg | S31: CO2 | T31: 1 | U31: =('Summary Table'!C26) -> 97.538491 | V31: =('Summary Table'!D26) -> 90.678662 | W31: =('Summary Table'!E26) -> 75.527743 | X31: =('Summary Table'!F26) -> 86.415413 | Y31: =('Summary Table'!G26) -> 81.24685 | Z31: =('Summary Table'!H26) -> 58.711775 | AA31: =('Summary Table'!I26) -> 63.396293 | AB31: =('Summary Table'!J26) -> 72.207404 | ... BA31: =('Summary Table'!AI26) -> 20.522249
A32: GHG | B32: Energy | C32: Fossil Fuel Combustion | D32: Electricity Generation | K32: Geothermal | M32: National | O32: 1.A.1.a. Public electricity and heat production | R32: Tg | S32: CO2 | T32: 1 | U32: =('Summary Table'!C28) -> 0.53819392 | V32: =('Summary Table'!D28) -> 0.53913329 | W32: =('Summary Table'!E28) -> 0.54407239 | X32: =('Summary Table'!F28) -> 0.55549804 | Y32: =('Summary Table'!G28) -> 0.51416615 | Z32: =('Summary Table'!H28) -> 0.4278974 | AA32: =('Summary Table'!I28) -> 0.46247774 | AB32: =('Summary Table'!J28) -> 0.48008445 | ... BA32: =('Summary Table'!AI28) -> 0.38055713
A33: GHG | B33: Energy | C33: Fossil Fuel Combustion | D33: US Territories | K33: Coal | M33: National | O33: 1.A.5. Other | R33: Tg | S33: CO2 | T33: 1 | U33: =('Summary Table'!C13) -> 0.49918364 | V33: =('Summary Table'!D13) -> 0.46298199 | W33: =('Summary Table'!E13) -> 0.3954042 | X33: =('Summary Table'!F13) -> 0.41466458 | Y33: =('Summary Table'!G13) -> 0.42259532 | Z33: =('Summary Table'!H13) -> 0.43052606 | AA33: =('Summary Table'!I13) -> 0.4418557 | AB33: =('Summary Table'!J13) -> 0.44910667 | ... BA33: =('Summary Table'!AI13) -> 2.888569
A34: GHG | B34: Energy | C34: Fossil Fuel Combustion | D34: US Territories | K34: Natural Gas | M34: National | O34: 1.A.5. Other | R34: Tg | S34: CO2 | T34: 1 | U34: =('Summary Table'!C20) -> NO | V34: =('Summary Table'!D20) -> NO | W34: =('Summary Table'!E20) -> NO | X34: =('Summary Table'!F20) -> NO | Y34: =('Summary Table'!G20) -> NO | Z34: =('Summary Table'!H20) -> NO | AA34: =('Summary Table'!I20) -> NO | AB34: =('Summary Table'!J20) -> NO | ... BA34: =('Summary Table'!AI20) -> 3.919756
A35: GHG | B35: Energy | C35: Fossil Fuel Combustion | D35: US Territories | K35: Petroleum | M35: National | O35: 1.A.5. Other | R35: Tg | S35: CO2 | T35: 1 | U35: =('Summary Table'!C27) -> 19.50896 | V35: =('Summary Table'!D27) -> 18.719463 | W35: =('Summary Table'!E27) -> 21.550453 | X35: =('Summary Table'!F27) -> 22.209566 | Y35: =('Summary Table'!G27) -> 24.30933 | Z35: =('Summary Table'!H27) -> 21.118063 | AA35: =('Summary Table'!I27) -> 19.336238 | AB35: =('Summary Table'!J27) -> 19.632813 | ... BA35: =('Summary Table'!AI27) -> 16.958327
A36: GHG | B36: Energy | C36: Non-Energy Uses of Fossil Fuels | D36: Industrial | M36: National | O36: 1.A.5. Other | R36: Tg | S36: CO2 | T36: 1 | U36: ='Non-Energy Use'!E157 -> 88.302765 | V36: ='Non-Energy Use'!F157 -> 92.387602 | W36: ='Non-Energy Use'!G157 -> 99.548101 | X36: ='Non-Energy Use'!H157 -> 87.59689 | Y36: ='Non-Energy Use'!I157 -> 98.135911 | Z36: ='Non-Energy Use'!J157 -> 94.070486 | AA36: ='Non-Energy Use'!K157 -> 89.727853 | AB36: ='Non-Energy Use'!L157 -> 100.61528 | ... BA36: ='Non-Energy Use'!AK157 -> 107.52289
A37: GHG | B37: Energy | C37: Non-Energy Uses of Fossil Fuels | D37: Transportation | M37: National | O37: 1.A.5. Other | R37: Tg | S37: CO2 | T37: 1 | U37: ='Non-Energy Use'!E174 -> 11.838675 | V37: ='Non-Energy Use'!F174 -> 10.590906 | W37: ='Non-Energy Use'!G174 -> 10.797881 | X37: ='Non-Energy Use'!H174 -> 10.995035 | Y37: ='Non-Energy Use'!I174 -> 11.49199 | Z37: ='Non-Energy Use'!J174 -> 11.294702 | AA37: ='Non-Energy Use'!K174 -> 10.961335 | AB37: ='Non-Energy Use'!L174 -> 11.579435 | ... BA37: ='Non-Energy Use'!AK174 -> 8.4341144
A38: GHG | B38: Energy | C38: Non-Energy Uses of Fossil Fuels | D38: US Territories | M38: National | O38: 1.A.5. Other | R38: Tg | S38: CO2 | T38: 1 | U38: ='Non-Energy Use'!E176 -> 3.354847 | V38: ='Non-Energy Use'!F176 -> 4.2506398 | W38: ='Non-Energy Use'!G176 -> 2.3504529 | X38: ='Non-Energy Use'!H176 -> 2.5647582 | Y38: ='Non-Energy Use'!I176 -> 2.0077956 | Z38: ='Non-Energy Use'!J176 -> 3.6616385 | AA38: ='Non-Energy Use'!K176 -> 4.802799 | AB38: ='Non-Energy Use'!L176 -> 5.1118096 | ... BA38: ='Non-Energy Use'!AK176 -> 0.070310903

Sheet InvDB-Old
A1: Inventory Database Input Template
A3: Template Instructions:
A4: Columns J through AP should reflect emission for 1990 through the current year. Please correct underlying formulas if source data cells are moved. If revisions to the sector, source, subsource, fuel, subreference, or gas columns are needed, or additional rows are needed please contact huppertm@saic.com to ensure InvDB reference data is updated accordingly. Note: Ne (Not Occuring) NE (Not Estimated).
A8: Source | C8: CO2 From Fossil Fuel Combustion
A9: Author Name | K9: Conversion Factor
A10: Author Phone | K10: KT per Tg | L10: 1000
A11: Publication Year | C11: 2024
A12: Report Type | C12: INTERIM
A15: All Values in Gas Quantities (Tg)
A16: Sector | B16: Source | C16: Subsource | D16: Fuel | E16: Subref | F16: 2nd Ref | G16: State | H16: Exclude | I16: GHG | J16: 1990 | K16: 1991 | L16: 1992 | M16: 1993 | N16: 1994 | O16: 1995 | P16: 1996 | Q16: 1997 | R16: 1998 | S16: 1999 | T16: 2000 | U16: 2001 | V16: 2002 | W16: 2003 | X16: 2004 | Y16: 2005 | Z16: 2006 | AA16: 2007 | AB16: 2008 | AC16: 2009 | AD16: 2010 | AE16: 2011 | AF16: 2012 | AG16: 2013 | AH16: 2014 | AI16: 2015 | AJ16: 2016 | AK16: 2017 | AL16: 2018 | AM16: 2019 | AN16: 2020 | AO16: 2021 | AP16: 2022
A17: Energy | B17: Fossil Fuel Combustion | C17: Residential | D17: Coal | I17: CO2 | J17: =('Summary Table'!C8) -> 2.9876953 | K17: =('Summary Table'!D8) -> 2.4418666 | L17: =('Summary Table'!E8) -> 2.4754382 | M17: =('Summary Table'!F8) -> 2.4697528 | N17: =('Summary Table'!G8) -> 1.9941821 | O17: =('Summary Table'!H8) -> 1.6716718 | P17: =('Summary Table'!I8) -> 1.5825802 | Q17: =('Summary Table'!J8) -> 1.5181716 | ... AP17: =('Summary Table'!AI8) -> 0
A18: Energy | B18: Fossil Fuel Combustion | C18: Residential | D18: Natural Gas | I18: CO2 | J18: =('Summary Table'!C15) -> 237.79751 | K18: =('Summary Table'!D15) -> 247.31637 | L18: =('Summary Table'!E15) -> 254.59498 | M18: =('Summary Table'!F15) -> 268.22933 | N18: =('Summary Table'!G15) -> 262.94356 | O18: =('Summary Table'!H15) -> 262.76571 | P18: =('Summary Table'!I15) -> 283.99195 | Q18: =('Summary Table'!J15) -> 270.12382 | ... AP18: =('Summary Table'!AI15) -> 271.98682
A19: Energy | B19: Fossil Fuel Combustion | C19: Residential | D19: Petroleum | I19: CO2 | J19: =('Summary Table'!C22) -> 97.782412 | K19: =('Summary Table'!D22) -> 97.95217 | L19: =('Summary Table'!E22) -> 96.897398 | M19: =('Summary Table'!F22) -> 95.382683 | N19: =('Summary Table'!G22) -> 92.10948 | O19: =('Summary Table'!H22) -> 88.696195 | P19: =('Summary Table'!I22) -> 97.899891 | Q19: =('Summary Table'!J22) -> 93.391359 | ... AP19: =('Summary Table'!AI22) -> 61.113012
A20: Energy | B20: Fossil Fuel Combustion | C20: Commercial | D20: Coal | I20: CO2 | J20: =('Summary Table'!C9) -> 11.950781 | K20: =('Summary Table'!D9) -> 11.123952 | L20: =('Summary Table'!E9) -> 11.276792 | M20: =('Summary Table'!F9) -> 11.251192 | N20: =('Summary Table'!G9) -> 11.30011 | O20: =('Summary Table'!H9) -> 11.187394 | P20: =('Summary Table'!I9) -> 11.605302 | Q20: =('Summary Table'!J9) -> 12.2835 | ... AP20: =('Summary Table'!AI9) -> 1.3881297
A21: Energy | B21: Fossil Fuel Combustion | C21: Commercial | D21: Natural Gas | I21: CO2 | J21: =('Summary Table'!C16) -> 142.02474 | K21: =('Summary Table'!D16) -> 148.12843 | L21: =('Summary Table'!E16) -> 152.14428 | M21: =('Summary Table'!F16) -> 154.86031 | N21: =('Summary Table'!G16) -> 157.02801 | O21: =('Summary Table'!H16) -> 164.20846 | P21: =('Summary Table'!I16) -> 171.12094 | Q21: =('Summary Table'!J16) -> 174.2504 | ... AP21: =('Summary Table'!AI16) -> 192.26242
A22: Energy | B22: Fossil Fuel Combustion | C22: Commercial | D22: Petroleum | I22: CO2 | J22: =('Summary Table'!C23) -> 74.317009 | K22: =('Summary Table'!D23) -> 73.407834 | L22: =('Summary Table'!E23) -> 64.61673 | M22: =('Summary Table'!F23) -> 56.873975 | N22: =('Summary Table'!G23) -> 56.369485 | O22: =('Summary Table'!H23) -> 52.39124 | P22: =('Summary Table'!I23) -> 54.832061 | Q22: =('Summary Table'!J23) -> 51.284956 | ... AP22: =('Summary Table'!AI23) -> 51.063465
A23: Energy | B23: Fossil Fuel Combustion | C23: Industrial | D23: Coal | I23: CO2 | J23: =('Summary Table'!C10) -> 157.83904 | K23: =('Summary Table'!D10) -> 154.63822 | L23: =('Summary Table'!E10) -> 150.27496 | M23: =('Summary Table'!F10) -> 152.54779 | N23: =('Summary Table'!G10) -> 153.46903 | O23: =('Summary Table'!H10) -> 147.21569 | P23: =('Summary Table'!I10) -> 140.08938 | Q23: =('Summary Table'!J10) -> 140.23965 | ... AP23: =('Summary Table'!AI10) -> 42.659993
A24: Energy | B24: Fossil Fuel Combustion | C24: Industrial | D24: Natural Gas | I24: CO2 | J24: =('Summary Table'!C17) -> 407.44058 | K24: =('Summary Table'!D17) -> 413.59445 | L24: =('Summary Table'!E17) -> 429.30738 | M24: =('Summary Table'!F17) -> 436.9822 | N24: =('Summary Table'!G17) -> 438.20865 | O24: =('Summary Table'!H17) -> 461.468 | P24: =('Summary Table'!I17) -> 477.22705 | Q24: =('Summary Table'!J17) -> 477.88613 | ... AP24: =('Summary Table'!AI17) -> 511.44589
A25: Energy | B25: Fossil Fuel Combustion | C25: Industrial | D25: Petroleum | I25: CO2 | J25: ='Summary Table'!C24 -> 305.86837 | K25: ='Summary Table'!D24 -> 292.78504 | L25: ='Summary Table'!E24 -> 301.03099 | M25: ='Summary Table'!F24 -> 293.10936 | N25: ='Summary Table'!G24 -> 288.92185 | O25: ='Summary Table'!H24 -> 291.98617 | P25: ='Summary Table'!I24 -> 300.13888 | Q25: ='Summary Table'!J24 -> 294.15681 | ... AP25: ='Summary Table'!AI24 -> 221.75315
A26: Energy | B26: Fossil Fuel Combustion | C26: Transportation | D26: Coal | I26: CO2 | J26: =('Summary Table'!C11) -> NO | K26: =('Summary Table'!D11) -> NO | L26: =('Summary Table'!E11) -> NO | M26: =('Summary Table'!F11) -> NO | N26: =('Summary Table'!G11) -> NO | O26: =('Summary Table'!H11) -> NO | P26: =('Summary Table'!I11) -> NO | Q26: =('Summary Table'!J11) -> NO | ... AP26: =('Summary Table'!AI11) -> NO
A27: Energy | B27: Fossil Fuel Combustion | C27: Transportation | D27: Natural Gas | I27: CO2 | J27: =('Summary Table'!C18) -> 36.000629 | K27: =('Summary Table'!D18) -> 32.870999 | L27: =('Summary Table'!E18) -> 32.223566 | M27: =('Summary Table'!F18) -> 34.154614 | N27: =('Summary Table'!G18) -> 37.562805 | O27: =('Summary Table'!H18) -> 38.39776 | P27: =('Summary Table'!I18) -> 39.083768 | Q27: =('Summary Table'!J18) -> 41.387043 | ... AP27: =('Summary Table'!AI18) -> 70.161309
A28: Energy | B28: Fossil Fuel Combustion | C28: Transportation | D28: Petroleum | I28: CO2 | J28: ='Summary Table'!C25 -> 1432.9433 | K28: ='Summary Table'!D25 -> 1389.4564 | L28: ='Summary Table'!E25 -> 1445.4199 | M28: ='Summary Table'!F25 -> 1474.4524 | N28: ='Summary Table'!G25 -> 1516.3845 | O28: ='Summary Table'!H25 -> 1542.2801 | P28: ='Summary Table'!I25 -> 1588.2793 | Q28: ='Summary Table'!J25 -> 1602.1285 | ... AP28: ='Summary Table'!AI25 -> 1710.6019
A29: Energy | B29: Fossil Fuel Combustion | C29: Electricity Generation | D29: Coal | I29: CO2 | J29: =('Summary Table'!C12) -> 1546.5139 | K29: =('Summary Table'!D12) -> 1547.1745 | L29: =('Summary Table'!E12) -> 1568.5415 | M29: =('Summary Table'!F12) -> 1631.6188 | N29: =('Summary Table'!G12) -> 1637.8528 | O29: =('Summary Table'!H12) -> 1659.8609 | P29: =('Summary Table'!I12) -> 1751.5234 | Q29: =('Summary Table'!J12) -> 1796.0189 | ... AP29: =('Summary Table'!AI12) -> 851.47206
A30: Energy | B30: Fossil Fuel Combustion | C30: Electricity Generation | D30: Natural Gas | I30: CO2 | J30: =('Summary Table'!C19) -> 175.36004 | K30: =('Summary Table'!D19) -> 178.96642 | L30: =('Summary Table'!E19) -> 186.07466 | M30: =('Summary Table'!F19) -> 187.58235 | N30: =('Summary Table'!G19) -> 210.85462 | O30: =('Summary Table'!H19) -> 228.17266 | P30: =('Summary Table'!I19) -> 204.86081 | Q30: =('Summary Table'!J19) -> 218.81343 | ... AP30: =('Summary Table'!AI19) -> 659.30521
A31: Energy | B31: Fossil Fuel Combustion | C31: Electricity Generation | D31: Petroleum | I31: CO2 | J31: =('Summary Table'!C26) -> 97.538491 | K31: =('Summary Table'!D26) -> 90.678662 | L31: =('Summary Table'!E26) -> 75.527743 | M31: =('Summary Table'!F26) -> 86.415413 | N31: =('Summary Table'!G26) -> 81.24685 | O31: =('Summary Table'!H26) -> 58.711775 | P31: =('Summary Table'!I26) -> 63.396293 | Q31: =('Summary Table'!J26) -> 72.207404 | ... AP31: =('Summary Table'!AI26) -> 20.522249
A32: Energy | B32: Fossil Fuel Combustion | C32: Electricity Generation | D32: Geothermal | I32: CO2 | J32: =('Summary Table'!C28) -> 0.53819392 | K32: =('Summary Table'!D28) -> 0.53913329 | L32: =('Summary Table'!E28) -> 0.54407239 | M32: =('Summary Table'!F28) -> 0.55549804 | N32: =('Summary Table'!G28) -> 0.51416615 | O32: =('Summary Table'!H28) -> 0.4278974 | P32: =('Summary Table'!I28) -> 0.46247774 | Q32: =('Summary Table'!J28) -> 0.48008445 | ... AP32: =('Summary Table'!AI28) -> 0.38055713
A33: Energy | B33: Fossil Fuel Combustion | C33: US Territories | D33: Coal | I33: CO2 | J33: =('Summary Table'!C13) -> 0.49918364 | K33: =('Summary Table'!D13) -> 0.46298199 | L33: =('Summary Table'!E13) -> 0.3954042 | M33: =('Summary Table'!F13) -> 0.41466458 | N33: =('Summary Table'!G13) -> 0.42259532 | O33: =('Summary Table'!H13) -> 0.43052606 | P33: =('Summary Table'!I13) -> 0.4418557 | Q33: =('Summary Table'!J13) -> 0.44910667 | ... AP33: =('Summary Table'!AI13) -> 2.888569
A34: Energy | B34: Fossil Fuel Combustion | C34: US Territories | D34: Natural Gas | I34: CO2 | J34: =('Summary Table'!C20) -> NO | K34: =('Summary Table'!D20) -> NO | L34: =('Summary Table'!E20) -> NO | M34: =('Summary Table'!F20) -> NO | N34: =('Summary Table'!G20) -> NO | O34: =('Summary Table'!H20) -> NO | P34: =('Summary Table'!I20) -> NO | Q34: =('Summary Table'!J20) -> NO | ... AP34: =('Summary Table'!AI20) -> 3.919756
A35: Energy | B35: Fossil Fuel Combustion | C35: US Territories | D35: Petroleum | I35: CO2 | J35: =('Summary Table'!C27) -> 19.50896 | K35: =('Summary Table'!D27) -> 18.719463 | L35: =('Summary Table'!E27) -> 21.550453 | M35: =('Summary Table'!F27) -> 22.209566 | N35: =('Summary Table'!G27) -> 24.30933 | O35: =('Summary Table'!H27) -> 21.118063 | P35: =('Summary Table'!I27) -> 19.336238 | Q35: =('Summary Table'!J27) -> 19.632813 | ... AP35: =('Summary Table'!AI27) -> 16.958327
A36: Energy | B36: Non-Energy Uses of Fossil Fuels | C36: Industrial | I36: CO2 | J36: ='Non-Energy Use'!E157 -> 88.302765 | K36: ='Non-Energy Use'!F157 -> 92.387602 | L36: ='Non-Energy Use'!G157 -> 99.548101 | M36: ='Non-Energy Use'!H157 -> 87.59689 | N36: ='Non-Energy Use'!I157 -> 98.135911 | O36: ='Non-Energy Use'!J157 -> 94.070486 | P36: ='Non-Energy Use'!K157 -> 89.727853 | Q36: ='Non-Energy Use'!L157 -> 100.61528 | ... AP36: ='Non-Energy Use'!AK157 -> 107.52289
A37: Energy | B37: Non-Energy Uses of Fossil Fuels | C37: Transportation | I37: CO2 | J37: ='Non-Energy Use'!E174 -> 11.838675 | K37: ='Non-Energy Use'!F174 -> 10.590906 | L37: ='Non-Energy Use'!G174 -> 10.797881 | M37: ='Non-Energy Use'!H174 -> 10.995035 | N37: ='Non-Energy Use'!I174 -> 11.49199 | O37: ='Non-Energy Use'!J174 -> 11.294702 | P37: ='Non-Energy Use'!K174 -> 10.961335 | Q37: ='Non-Energy Use'!L174 -> 11.579435 | ... AP37: ='Non-Energy Use'!AK174 -> 8.4341144
A38: Energy | B38: Non-Energy Uses of Fossil Fuels | C38: US Territories | I38: CO2 | J38: ='Non-Energy Use'!E176 -> 3.354847 | K38: ='Non-Energy Use'!F176 -> 4.2506398 | L38: ='Non-Energy Use'!G176 -> 2.3504529 | M38: ='Non-Energy Use'!H176 -> 2.5647582 | N38: ='Non-Energy Use'!I176 -> 2.0077956 | O38: ='Non-Energy Use'!J176 -> 3.6616385 | P38: ='Non-Energy Use'!K176 -> 4.802799 | Q38: ='Non-Energy Use'!L176 -> 5.1118096 | ... AP38: ='Non-Energy Use'!AK176 -> 0.070310903
F266: ='[5]Non-Ferrous Metals'!C16 -> 186.78981 | G266: ='[5]Non-Ferrous Metals'!D16 -> 186.78981 | H266: ='[5]Non-Ferrous Metals'!E16 -> 228.73179 | I266: ='[5]Non-Ferrous Metals'!F16 -> 270.67377 | J266: ='[5]Non-Ferrous Metals'!G16 -> 312.61575 | K266: ='[5]Non-Ferrous Metals'!H16 -> 403.80428 | L266: ='[5]Non-Ferrous Metals'!I16 -> 494.99281 | M266: ='[5]Non-Ferrous Metals'!J16 -> 586.18135 | ... AI266: ='[5]Non-Ferrous Metals'!AF16 -> 740.59181
F268: ='[5]Non-Ferrous Metals'!C21 -> 14.054458 | G268: ='[5]Non-Ferrous Metals'!D21 -> 13.837902 | H268: ='[5]Non-Ferrous Metals'!E21 -> 17.151318 | I268: ='[5]Non-Ferrous Metals'!F21 -> 20.103424 | J268: ='[5]Non-Ferrous Metals'!G21 -> 23.278721 | K268: ='[5]Non-Ferrous Metals'!H21 -> 29.540174 | L268: ='[5]Non-Ferrous Metals'!I21 -> 37.116037 | M268: ='[5]Non-Ferrous Metals'!J21 -> 44.116366 | ... AI268: ='[5]Non-Ferrous Metals'!AF21 -> 54.865878
F272: ='[5]Non-Ferrous Metals'!C17 -> 1119.1272 | G272: ='[5]Non-Ferrous Metals'!D17 -> 1119.1272 | H272: ='[5]Non-Ferrous Metals'!E17 -> 2137.5056 | I272: ='[5]Non-Ferrous Metals'!F17 -> 3155.884 | J272: ='[5]Non-Ferrous Metals'!G17 -> 4174.2623 | K272: ='[5]Non-Ferrous Metals'!H17 -> 7467.3147 | L272: ='[5]Non-Ferrous Metals'!I17 -> 10760.367 | M272: ='[5]Non-Ferrous Metals'!J17 -> 14053.419 | ... AI272: ='[5]Non-Ferrous Metals'!AF17 -> 11680.489
F274: ='[5]Non-Ferrous Metals'!C22 -> 100.36681 | G274: ='[5]Non-Ferrous Metals'!D22 -> 100.62443 | H274: ='[5]Non-Ferrous Metals'!E22 -> 192.07171 | I274: ='[5]Non-Ferrous Metals'!F22 -> 282.52483 | J274: ='[5]Non-Ferrous Metals'!G22 -> 373.71172 | K274: ='[5]Non-Ferrous Metals'!H22 -> 669.1956 | L274: ='[5]Non-Ferrous Metals'!I22 -> 962.70494 | M274: ='[5]Non-Ferrous Metals'!J22 -> 1257.4894 | ... AI274: ='[5]Non-Ferrous Metals'!AF22 -> 1058.3067
F278: ='[5]Non-Ferrous Metals'!C18 -> 53013.757 | G278: ='[5]Non-Ferrous Metals'!D18 -> 54004.658 | H278: ='[5]Non-Ferrous Metals'!E18 -> 54995.56 | I278: ='[5]Non-Ferrous Metals'!F18 -> 55986.462 | J278: ='[5]Non-Ferrous Metals'!G18 -> 56977.364 | K278: ='[5]Non-Ferrous Metals'!H18 -> 59704.186 | L278: ='[5]Non-Ferrous Metals'!I18 -> 62431.007 | M278: ='[5]Non-Ferrous Metals'!J18 -> 65157.829 | ... AI278: ='[5]Non-Ferrous Metals'!AF18 -> 44919.162
F280: ='[5]Non-Ferrous Metals'!C23 -> 2771.7209 | G280: ='[5]Non-Ferrous Metals'!D23 -> 2837.1118 | H280: ='[5]Non-Ferrous Metals'!E23 -> 2875.35 | I280: ='[5]Non-Ferrous Metals'!F23 -> 2937.4582 | J280: ='[5]Non-Ferrous Metals'!G23 -> 2982.5347 | K280: ='[5]Non-Ferrous Metals'!H23 -> 3131.7708 | L280: ='[5]Non-Ferrous Metals'!I23 -> 3250.3999 | M280: ='[5]Non-Ferrous Metals'!J23 -> 3392.2103 | ... AI280: ='[5]Non-Ferrous Metals'!AF23 -> 2342.6127
F297: =[5]Chemicals!C16 -> 32405.324 | G297: =[5]Chemicals!D16 -> 34694.879 | H297: =[5]Chemicals!E16 -> 36984.435 | I297: =[5]Chemicals!F16 -> 39273.99 | J297: =[5]Chemicals!G16 -> 41563.545 | K297: =[5]Chemicals!H16 -> 40312.731 | L297: =[5]Chemicals!I16 -> 39061.917 | M297: =[5]Chemicals!J16 -> 37811.103 | ... AI297: =[5]Chemicals!AF16 -> 7935.4136
F299: =[5]Chemicals!C21 -> 2438.2447 | G299: =[5]Chemicals!D21 -> 2570.2919 | H299: =[5]Chemicals!E21 -> 2773.2561 | I299: =[5]Chemicals!F21 -> 2916.9494 | J299: =[5]Chemicals!G21 -> 3095.0013 | K299: =[5]Chemicals!H21 -> 2949.065 | L299: =[5]Chemicals!I21 -> 2928.979 | M299: =[5]Chemicals!J21 -> 2845.6867 | ... AI299: =[5]Chemicals!AF21 -> 587.88584
...

Sheet Summary Table
A1: U.S. CO2 Emission Trends from Fossil Fuel Combustion
A2: This sheet summarizes U.S. CO2 emissions from fossil fuel combustion by fuel type and sector and then by sector and fuel type.
A3: Non-energy use carbon stored and international bunker fuel emissions are also reported separately.
B5: Table 2-3: CO2 Emissions from Fossil Fuel Combustion by Fuel Type and Sector (MMT CO2 Eq.)
B6: Fuel Type/Sector | C6: 1990 | D6: 1991 | E6: 1992 | F6: 1993 | G6: 1994 | H6: 1995 | I6: 1996 | J6: 1997 | K6: 1998 | L6: 1999 | M6: 2000 | N6: 2001 | O6: 2002 | P6: 2003 | Q6: 2004 | R6: 2005 | S6: 2006 | T6: 2007 | U6: 2008 | V6: 2009 | W6: 2010 | X6: 2011 | Y6: 2012 | Z6: 2013 | AA6: 2014 | AB6: 2015 | AC6: 2016 | AD6: 2017 | AE6: 2018 | AF6: 2019 | AG6: 2020 | AH6: 2021 | AI6: 2022 | AJ6: 90-22 | AK6: 20-21 | AL6: 21-22
B7: Coal | C7: =SUM(C8:C13) -> 1719.7906 | D7: =SUM(D8:D13) -> 1715.8415 | E7: =SUM(E8:E13) -> 1732.9641 | F7: =SUM(F8:F13) -> 1798.3022 | G7: =SUM(G8:G13) -> 1805.0388 | H7: =SUM(H8:H13) -> 1820.3662 | I7: =SUM(I8:I13) -> 1905.2425 | J7: =SUM(J8:J13) -> 1950.5093 | ... AI7: =SUM(AI8:AI13) -> 898.40875 | AJ7: =IFERROR((AI7-$C7)/$C7,"NA") -> -0.47760572 | AK7: =IFERROR((AH7-AG7)/AG7,"NA") -> 0.14577105 | AL7: =IFERROR((AI7-AH7)/AH7,"NA") -> -0.061625748 | AN7: =AI7/AI30 -> 0.19156316 | AO7: Coal % of Total Emissions
B8: Residential | C8: =C59*CtoCO2 -> 2.9876953 | D8: =D59*CtoCO2 -> 2.4418666 | E8: =E59*CtoCO2 -> 2.4754382 | F8: =F59*CtoCO2 -> 2.4697528 | G8: =G59*CtoCO2 -> 1.9941821 | H8: =H59*CtoCO2 -> 1.6716718 | I8: =I59*CtoCO2 -> 1.5825802 | J8: =J59*CtoCO2 -> 1.5181716 | ... AI8: =AI59*CtoCO2 -> 0 | AJ8: =IFERROR((AI8-$C8)/$C8,"NA") -> -1 | AK8: =IFERROR((AH8-AG8)/AG8,"NA") -> NA | AL8: =IFERROR((AI8-AH8)/AH8,"NA") -> NA
B9: Commercial | C9: =C60*CtoCO2 -> 11.950781 | D9: =D60*CtoCO2 -> 11.123952 | E9: =E60*CtoCO2 -> 11.276792 | F9: =F60*CtoCO2 -> 11.251192 | G9: =G60*CtoCO2 -> 11.30011 | H9: =H60*CtoCO2 -> 11.187394 | I9: =I60*CtoCO2 -> 11.605302 | J9: =J60*CtoCO2 -> 12.2835 | ... AI9: =AI60*CtoCO2 -> 1.3881297 | AJ9: =IFERROR((AI9-$C9)/$C9,"NA") -> -0.88384611 | AK9: =IFERROR((AH9-AG9)/AG9,"NA") -> 0.025688708 | AL9: =IFERROR((AI9-AH9)/AH9,"NA") -> -0.029562883
B10: Industrial | C10: =C61*CtoCO2 -> 157.83904 | D10: =D61*CtoCO2 -> 154.63822 | E10: =E61*CtoCO2 -> 150.27496 | F10: =F61*CtoCO2 -> 152.54779 | G10: =G61*CtoCO2 -> 153.46903 | H10: =H61*CtoCO2 -> 147.21569 | I10: =I61*CtoCO2 -> 140.08938 | J10: =J61*CtoCO2 -> 140.23965 | ... AI10: =AI61*CtoCO2 -> 42.659993 | AJ10: =IFERROR((AI10-$C10)/$C10,"NA") -> -0.72972471 | AK10: =IFERROR((AH10-AG10)/AG10,"NA") -> 0.0013989318 | AL10: =IFERROR((AI10-AH10)/AH10,"NA") -> -0.0085159048
